В этом примере мы создаем три объекта класса Person: p1, p2 и p3. Объект p1 выбрасывает исключение TypeError, так как в конструктор передается строка вместо целого числа для аргумента age. Объект p2 выбрасывает исключение ValueError, потому что значение аргумента age находится за пределами допустимого диапазона. Объект p3 создается успешно, и мы вызываем его методы introduce и have_birthday, которые должны работать без ошибок. Однако после этого мы пытаемся изменить значение атрибута name объекта p3 на целое число, что приводит к возникновению исключения TypeError. В блоке except мы ловим любое исключение TypeError или ValueError и выводим соответствующее сообщение об ошибке. Если возникнет любое другое исключение, мы выведем сообщение об ошибке по умолчанию.

Затем мы создаем три пользовательских исключения CustomExceptionOne, CustomExceptionTwo и CustomExceptionThree и вызываем каждое из них в блоках try-except. Если исключение было вызвано, мы ловим его в соответствующем блоке except и выводим сообщение об ошибке.
